08/05/2024 20:52:00 - __main__ - DEBUG - Hello 
08/05/2024 20:52:49 - __main__ - ERROR - list index out of range 
Traceback (most recent call last):
  File "/Users/parultiwari/Documents/Coding/python/Python-Intermediate_revision/Python_intermediate_revision/Logging/logging_stacktraces.py", line 14, in <module>
    b = a[4] #index out of range
        ~^^^
IndexError: list index out of range
08/05/2024 20:55:27 - __main__ - ERROR - list index out of range 
Traceback (most recent call last):
  File "/Users/parultiwari/Documents/Coding/python/Python-Intermediate_revision/Python_intermediate_revision/Logging/logging_stacktraces.py", line 15, in <module>
    b = a[4] #index out of range
        ~^^^
IndexError: list index out of range
08/05/2024 20:55:27 - __main__ - ERROR - This is the error Traceback (most recent call last):
  File "/Users/parultiwari/Documents/Coding/python/Python-Intermediate_revision/Python_intermediate_revision/Logging/logging_stacktraces.py", line 21, in <module>
    b = a[4] #index out of range
        ~^^^
IndexError: list index out of range
 
08/05/2024 21:11:54 - __main__ - ERROR - list index out of range 
Traceback (most recent call last):
  File "/Users/parultiwari/Documents/Coding/python/Python-Intermediate_revision/Python_intermediate_revision/Logging/logging_stacktraces.py", line 15, in <module>
    b = a[4] #index out of range
        ~^^^
IndexError: list index out of range
08/05/2024 21:11:54 - __main__ - ERROR - This is the error Traceback (most recent call last):
  File "/Users/parultiwari/Documents/Coding/python/Python-Intermediate_revision/Python_intermediate_revision/Logging/logging_stacktraces.py", line 21, in <module>
    b = a[4] #index out of range
        ~^^^
IndexError: list index out of range
 
